Workbook

Sheet Scoring Format
A1: Category | B1: Pts
A2: Pts per Passing Yard | B2: 0.05
A3: Pts per Rushing Yard | B3: 0.1
A4: Pts per Receiving Yard | B4: 0.1
A5: Pts per Pass TD | B5: 4
A6: Pts per Rush TD | B6: 6
A7: Pts per Rec TD | B7: 6
A8: Pts per Turnover | B8: -1

Sheet ARI
A1: Arizona Cardinals
A3: Team Projections Menu | AD3: Team Projections Menu
I5: RSP Projections: Year 1 | N5: Adjustable Projections: Year 1 | T5: Offense Distribution | AK5: RSP Projections: Year 1 | AP5: Adjustable Projections: Year 1
I6: RSP Projections: Year 2 | N6: Past Run/Pass Performances | T6: Run | U6: Pass | AK6: RSP Projections: Year 2
T7: =(N17+D27+L38+L47)/(N17+D27+L38+D17) -> 0.39219713 | U7: =D17/(D17+N17+D27+L38+L47) -> 0.60780287
A10: RSP Projections: Year 1 | AD10: Adjustable Projections: Year 1
D12: Passing | M12: Rushing | S12: Touches | W12: Fantasy Points | AF12: Passing | AO12: Rushing | AU12: Touches | AY12: Fantasy Points
A13: QB | B13: Age | C13: G | D13: Att | E13: Comp | F13: Pct | G13: Yards | H13: Yds/Att | I13: TDs | J13: TDs/Att | K13: Int | L13: Int/Att | N13: Ratt | O13: Ryds | P13: Ryds/Att | Q13: TDs | R13: Tds/Att | T13: Touch % | U13: Pct Pass | V13: Pct Run | X13: Fpts | Y13: Adjusted | AD13: QB | AE13: G | AF13: Att | AG13: Comp | AH13: Pct | AI13: Yards | AJ13: Yds/Att | AK13: TDs | AL13: TDs/Att | AM13: Int | AN13: Int/Att | AP13: Ratt | AQ13: Ryds | AR13: Ryds/Att | AS13: TDs | AT13: Tds/Att | AV13: Touch % | AW13: Pct Pass | AX13: Pct Run | AZ13: Fpts | BA13: Adjusted
A14: QB*Brissett, Jacoby - ARI | B14: 33 | C14: 17 | D14: 592 | E14: 403 | F14: =E14/D14 -> 0.68074324 | G14: 4542 | H14: =G14/D14 -> 7.6722973 | I14: 28 | J14: =I14/D14 -> 0.047297297 | K14: 11 | L14: =K14/D14 -> 0.018581081 | N14: 46 | O14: 195 | P14: =O14/N14 -> 4.2391304 | Q14: 2 | R14: =Q14/N14 -> 0.043478261 | T14: =(D14+N14)/($D$17+$N$17) -> 1 | U14: =D14/($D$17) -> 1 | V14: =N14/($N$17) -> 1 | X14: =($G14*('Scoring Format'!$B$2))+($I14*('Scoring Format'!$B$5))+($K14*('Scoring Format'!$B$8))+($O14*('Scoring Format'!$B$3))+($Q14*('Scoring Format'!$B$6)) -> 359.6 | Y14: =(($G14*('Scoring Format'!$B$2))+($I14*('Scoring Format'!$B$5))+($K14*('Scoring Format'!$B$8))+($O14*('Scoring Format'!$B$3))+($Q14*('Scoring Format'!$B$6)))*0.4 -> 143.84 | AD14: Murray, Kyler - ARI | AF14: 583 | AG14: 378 | AH14: =AG14/AF14 -> 0.6483705 | AI14: 4072 | AJ14: =AI14/AF14 -> 6.9845626 | AK14: 27 | AL14: =AK14/AF14 -> 0.046312178 | AM14: 11 | AN14: =AM14/AF14 -> 0.018867925 | AP14: 100 | AQ14: 590 | AR14: =AQ14/AP14 -> 5.9 | AS14: 5 | AT14: =AS14/AP14 -> 0.05 | AV14: =(AF14+AP14)/(AF17+AP17) -> 1 | AW14: =AF14/(AP14+AF14) -> 0.85358712 | AX14: =AP14/(AF14+AP14) -> 0.14641288 | AZ14: =((AI14*0.05)+(AK14*4)+(AM14*-1)+(AQ14*0.1)+(AS14*6))*0.55 -> 214.28 | BA14: =((AI14*0.05)+(AK14*4)+(AM14*-1)+(AQ14*0.1)+(AS14*6))*0.4 -> 155.84
A15: QB*Minshew, Gardner - ARI | B15: 30 | F15: =E15/D15 -> #DIV/0! | H15: =G15/D15 -> #DIV/0! | J15: =I15/D15 -> #DIV/0! | L15: =K15/D15 -> #DIV/0! | P15: =O15/N15 -> #DIV/0! | R15: =Q15/N15 -> #DIV/0! | T15: =(D15+N15)/($D$17+$N$17) -> 0 | U15: =D15/($D$17) -> 0 | V15: =N15/($N$17) -> 0 | X15: =($G15*('Scoring Format'!$B$2))+($I15*('Scoring Format'!$B$5))+($K15*('Scoring Format'!$B$8))+($O15*('Scoring Format'!$B$3))+($Q15*('Scoring Format'!$B$6)) -> 0 | Y15: =(($G15*('Scoring Format'!$B$2))+($I15*('Scoring Format'!$B$5))+($K15*('Scoring Format'!$B$8))+($O15*('Scoring Format'!$B$3))+($Q15*('Scoring Format'!$B$6)))*0.4 -> 0 | AD15: McCoy, Colt - ARI | AF15: 0 | AG15: 0 | AH15: 0 | AI15: 0 | AK15: 0 | AL15: =AK15/AF15 -> #DIV/0! | AM15: 0 | AN15: =AM15/AF15 -> #DIV/0! | AP15: 0 | AQ15: 0 | AS15: 0 | AT15: =AS15/AP15 -> #DIV/0! | AV15: =(AF15+AP15)/(AE18+AO18) -> #DIV/0! | AW15: =AF15/(AP15+AF15) -> #DIV/0! | AX15: =AP15/(AF15+AP15) -> #DIV/0!
A16: QB*Beck, Carson - ARI | B16: 24 | F16: =E16/D16 -> #DIV/0! | H16: =G16/D16 -> #DIV/0! | J16: =I16/D16 -> #DIV/0! | L16: =K16/D16 -> #DIV/0! | P16: =O16/N16 -> #DIV/0! | R16: =Q16/N16 -> #DIV/0! | T16: =(D16+N16)/($D$17+$N$17) -> 0 | U16: =D16/($D$17) -> 0 | V16: =N16/($N$17) -> 0 | X16: =($G16*('Scoring Format'!$B$2))+($I16*('Scoring Format'!$B$5))+($K16*('Scoring Format'!$B$8))+($O16*('Scoring Format'!$B$3))+($Q16*('Scoring Format'!$B$6)) -> 0 | Y16: =(($G16*('Scoring Format'!$B$2))+($I16*('Scoring Format'!$B$5))+($K16*('Scoring Format'!$B$8))+($O16*('Scoring Format'!$B$3))+($Q16*('Scoring Format'!$B$6)))*0.4 -> 0 | AD16: Streveler, Chris - ARI | AH16: =AG16/AF16 -> #DIV/0! | AJ16: =AI16/AF16 -> #DIV/0! | AL16: =AK16/AF16 -> #DIV/0! | AN16: =AM16/AF16 -> #DIV/0! | AR16: =AQ16/AP16 -> #DIV/0! | AT16: =AS16/AP16 -> #DIV/0! | AV16: =(AF16+AP16)/(AE20+AO20) -> #DIV/0! | AW16: =AF16/(AP16+AF16) -> #DIV/0! | AX16: =AP16/(AF16+AP16) -> #DIV/0! | AZ16: =((AI16*0.05)+(AK16*4)+(AM16*-1)+(AQ16*0.1)+(AS16*6))*0.55 -> 0 | BA16: =((AI16*0.05)+(AK16*4)+(AM16*-1)+(AQ16*0.1)+(AS16*6))*0.4 -> 0
A17: Total | D17: =SUM(D14:D16) -> 592 | E17: =SUM(E14:E16) -> 403 | G17: =SUM(G14:G16) -> 4542 | I17: =SUM(I14:I16) -> 28 | K17: =SUM(K14:K16) -> 11 | N17: =SUM(N14:N16) -> 46 | O17: =SUM(O14:O16) -> 195 | Q17: =SUM(Q14:Q16) -> 2 | T17: =T14+T15+T16 -> 1 | U17: =D17/(D17+N17) -> 0.92789969 | V17: =N17/(N17+D17) -> 0.072100313 | AD17: Total | AF17: =SUM(AF14:AF16) -> 583 | AG17: =SUM(AG14:AG16) -> 378 | AI17: =SUM(AI14:AI16) -> 4072 | AK17: =SUM(AK14:AK16) -> 27 | AM17: =SUM(AM14:AM16) -> 11 | AP17: =SUM(AP14:AP16) -> 100 | AQ17: =SUM(AQ14:AQ16) -> 590 | AS17: =SUM(AS14:AS16) -> 5 | AV17: =AV14+AV15+AV16 -> #DIV/0! | AW17: =AF17/(AF17+AP17) -> 0.85358712 | AX17: =AP17/(AP17+AF17) -> 0.14641288
A20: Rushing | I20: Receiving | S20: Touches | W20: Fantasy Points | AD20: Rushing | AK20: Receiving | AU20: Touches | AY20: Fantasy Points
A21: RB | B21: Age | C21: G | D21: Att | E21: Yards | F21: Yds/Att | G21: TDs | H21: TDs/Att | J21: Catch % | K21: Targets | L21: Rec | M21: Yds | N21: Yds/Rec | O21: TDs | P21: TDs/Rec | S21: RB | T21: Touch % | U21: Pct Pass | V21: Pct Run | X21: Fpts | Y21: PPR Fpts | Z21: .5 PPR | AD21: RB | AE21: G | AF21: Att | AG21: Yards | AH21: Yds/Att | AI21: TDs | AJ21: TDs/Att | AL21: Catch % | AM21: Targets | AN21: Rec | AO21: Yds | AP21: Yds/Rec | AQ21: TDs | AR21: TDs/Rec | AV21: Touch % | AW21: Pct Pass | AX21: Pct Run | AZ21: Fpts | BA21: PPR Fpts
A22: RB*Conner, James - ARI | B22: 31 | F22: =E22/D22 -> #DIV/0! | H22: =G22/D22 -> #DIV/0! | J22: =L22/K22 -> #DIV/0! | N22: =M22/L22 -> #DIV/0! | P22: =O22/L22 -> #DIV/0! | S22: Conner, James - ARI | T22: =(D22+K22)/($D$27+$K$27+$N$17+$E$17+$L$38+$L$47) -> 0 | U22: =K22/($K$27+$F$38+$F$47) -> 0 | V22: =D22/($D$27+$N$17+$L$38+$L$47) -> 0 | X22: =($E22*('Scoring Format'!$B$3))+($G22*('Scoring Format'!$B$6))+($M22*('Scoring Format'!$B$4))+($O22*('Scoring Format'!$B$7)) -> 0 | Y22: =($E22*('Scoring Format'!$B$3))+($G22*('Scoring Format'!$B$6))+(L22*1)+($M22*('Scoring Format'!$B$4))+($O22*('Scoring Format'!$B$7)) -> 0 | Z22: =($E22*('Scoring Format'!$B$3))+($G22*('Scoring Format'!$B$6))+(L22*0.5)+($M22*('Scoring Format'!$B$4))+($O22*('Scoring Format'!$B$7)) -> 0 | AD22: Conner, James - ARI | AF22: 200 | AG22: 1040 | AH22: =AG22/AF22 -> 5.2 | AI22: 7 | AJ22: =AI22/AF22 -> 0.035 | AL22: =AN22/AM22 -> 0.8 | AM22: 70 | AN22: 56 | AO22: 364 | AP22: =AO22/AN22 -> 6.5 | AQ22: 2 | AR22: =AQ22/AN22 -> 0.035714286 | AV22: =(#REF!+AM22)/(#REF!+AM25) -> #REF! | AW22: =#REF!/(AM22+#REF!) -> #REF! | AX22: =AM22/(#REF!+AM22) -> #REF! | AZ22: =(#REF!*0.1)+(AF22*6)+(AL22*0.1)+(AN22*6) -> #REF! | BA22: =(#REF!*0.1)+(AF22*6)+(AK22*1)+(AL22*0.1)+(AN22*6) -> #REF!
A23: RB*Benson, Trey - ARI | B23: 24 | F23: =E23/D23 -> #DIV/0! | H23: =G23/D23 -> #DIV/0! | J23: =L23/K23 -> #DIV/0! | N23: =M23/L23 -> #DIV/0! | P23: =O23/L23 -> #DIV/0! | S23: Benson, Trey - ARI | T23: =(D23+K23)/($D$27+$K$27+$N$17+$E$17+$L$38+$L$47) -> 0 | U23: =K23/($K$27+$F$38+$F$47) -> 0 | V23: =D23/($D$27+$N$17+$L$38+$L$47) -> 0 | X23: =($E23*('Scoring Format'!$B$3))+($G23*('Scoring Format'!$B$6))+($M23*('Scoring Format'!$B$4))+($O23*('Scoring Format'!$B$7)) -> 0 | Y23: =($E23*('Scoring Format'!$B$3))+($G23*('Scoring Format'!$B$6))+(L23*1)+($M23*('Scoring Format'!$B$4))+($O23*('Scoring Format'!$B$7)) -> 0 | Z23: =($E23*('Scoring Format'!$B$3))+($G23*('Scoring Format'!$B$6))+(L23*0.5)+($M23*('Scoring Format'!$B$4))+($O23*('Scoring Format'!$B$7)) -> 0 | AD23: Edmonds, Chase - ARI | AF23: 96 | AG23: 445 | AH23: =AG23/AF23 -> 4.6354167 | AI23: 6 | AJ23: =AI23/AF23 -> 0.0625 | AL23: =AN23/AM23 -> 0.58333333 | AM23: 24 | AN23: 14 | AO23: 110 | AP23: =AO23/AN23 -> 7.8571429 | AQ23: 2 | AR23: =AQ23/AN23 -> 0.14285714 | AV23: =(#REF!+AM23)/(#REF!+AM26) -> #REF! | AW23: =#REF!/(AM23+#REF!) -> #REF! | AX23: =AM23/(#REF!+AM23) -> #REF! | AZ23: =(#REF!*0.1)+(AF23*6)+(AL23*0.1)+(AN23*6) -> #REF! | BA23: =(#REF!*0.1)+(AF23*6)+(AK23*1)+(AL23*0.1)+(AN23*6) -> #REF!
A24: RB*Love, Jeremiyah - ARI | B24: 21 | C24: 17 | D24: 210 | E24: 900 | F24: =E24/D24 -> 4.2857143 | G24: 5 | H24: =G24/D24 -> 0.023809524 | J24: =L24/K24 -> 0.75609756 | K24: 82 | L24: 62 | M24: 482 | N24: =M24/L24 -> 7.7741935 | O24: 2 | P24: =O24/L24 -> 0.032258065 | S24: Love, Jeremiyah - ARI | T24: =(D24+K24)/($D$27+$K$27+$N$17+$E$17+$L$38+$L$47) -> 0.32336656 | U24: =K24/($K$27+$F$38+$F$47) -> 0.18894009 | V24: =D24/($D$27+$N$17+$L$38+$L$47) -> 0.54973822 | X24: =($E24*('Scoring Format'!$B$3))+($G24*('Scoring Format'!$B$6))+($M24*('Scoring Format'!$B$4))+($O24*('Scoring Format'!$B$7)) -> 180.2 | Y24: =($E24*('Scoring Format'!$B$3))+($G24*('Scoring Format'!$B$6))+(L24*1)+($M24*('Scoring Format'!$B$4))+($O24*('Scoring Format'!$B$7)) -> 242.2 | Z24: =($E24*('Scoring Format'!$B$3))+($G24*('Scoring Format'!$B$6))+(L24*0.5)+($M24*('Scoring Format'!$B$4))+($O24*('Scoring Format'!$B$7)) -> 211.2 | AD24: Benjamin, Eno - ARI | AF24: 8 | AG24: 28 | AH24: =AG24/AF24 -> 3.5 | AI24: 0 | AJ24: =AI24/AF24 -> 0 | AL24: =AN24/AM24 -> 0.5 | AM24: 4 | AN24: 2 | AO24: 17 | AP24: =AO24/AN24 -> 8.5 | AQ24: 0 | AR24: =AQ24/AN24 -> 0 | AV24: =(#REF!+AM24)/(#REF!+AL30) -> #REF! | AW24: =#REF!/(AM24+#REF!) -> #REF! | AX24: =AM24/(#REF!+AM24) -> #REF! | AZ24: =(#REF!*0.1)+(AF24*6)+(AL24*0.1)+(AN24*6) -> #REF! | BA24: =(#REF!*0.1)+(AF24*6)+(AK24*1)+(AL24*0.1)+(AN24*6) -> #REF!
A25: RB*Allgeier, Tyler - ARI | B25: 26 | C25: 17 | D25: 100 | E25: 360 | F25: =E25/D25 -> 3.6 | G25: 5 | H25: =G25/D25 -> 0.05 | J25: =L25/K25 -> 0.73333333 | K25: 15 | L25: 11 | M25: 70 | N25: =M25/L25 -> 6.3636364 | O25: 0 | P25: =O25/L25 -> 0 | S25: Allgeier, Tyler - ARI | T25: =(D25+K25)/($D$27+$K$27+$N$17+$E$17+$L$38+$L$47) -> 0.12735327 | U25: =K25/($K$27+$F$38+$F$47) -> 0.034562212 | V25: =D25/($D$27+$N$17+$L$38+$L$47) -> 0.2617801 | X25: =($E25*('Scoring Format'!$B$3))+($G25*('Scoring Format'!$B$6))+($M25*('Scoring Format'!$B$4))+($O25*('Scoring Format'!$B$7)) -> 73 | Y25: =($E25*('Scoring Format'!$B$3))+($G25*('Scoring Format'!$B$6))+(L25*1)+($M25*('Scoring Format'!$B$4))+($O25*('Scoring Format'!$B$7)) -> 84 | Z25: =($E25*('Scoring Format'!$B$3))+($G25*('Scoring Format'!$B$6))+(L25*0.5)+($M25*('Scoring Format'!$B$4))+($O25*('Scoring Format'!$B$7)) -> 78.5 | AD25: Ward, Jonathan - ARI | AH25: =AG25/AF25 -> #DIV/0! | AI25: 0 | AJ25: =AI25/AF25 -> #DIV/0! | AL25: =AN25/AM25 -> #DIV/0! | AP25: =AO25/AN25 -> #DIV/0! | AQ25: 0 | AR25: =AQ25/AN25 -> #DIV/0! | AV25: =(#REF!+AM25)/(#REF!+AM31) -> #REF! | AW25: =#REF!/(AM25+#REF!) -> #REF! | AX25: =AM25/(#REF!+AM25) -> #REF! | AZ25: =(#REF!*0.1)+(AF25*6)+(AL25*0.1)+(AN25*6) -> #REF! | BA25: =(#REF!*0.1)+(AF25*6)+(AK25*1)+(AL25*0.1)+(AN25*6) -> #REF!
A26: RB*Knight, Bam - ARI | B26: 25 | C26: 12 | D26: 21 | E26: 72 | F26: =E26/D26 -> 3.4285714 | G26: 0 | H26: =G26/D26 -> 0 | J26: =L26/K26 -> 0.66666667 | K26: 21 | L26: 14 | M26: 99 | N26: =M26/L26 -> 7.0714286 | O26: 1 | P26: =O26/L26 -> 0.071428571 | S26: Knight, Bam - ARI | T26: =(D26+K26)/($D$27+$K$27+$N$17+$E$17+$L$38+$L$47) -> 0.046511628 | U26: =K26/($K$27+$F$38+$F$47) -> 0.048387097 | V26: =D26/($D$27+$N$17+$L$38+$L$47) -> 0.054973822 | X26: =($E26*('Scoring Format'!$B$3))+($G26*('Scoring Format'!$B$6))+($M26*('Scoring Format'!$B$4))+($O26*('Scoring Format'!$B$7)) -> 23.1 | Y26: =($E26*('Scoring Format'!$B$3))+($G26*('Scoring Format'!$B$6))+(L26*1)+($M26*('Scoring Format'!$B$4))+($O26*('Scoring Format'!$B$7)) -> 37.1 | Z26: =($E26*('Scoring Format'!$B$3))+($G26*('Scoring Format'!$B$6))+(L26*0.5)+($M26*('Scoring Format'!$B$4))+($O26*('Scoring Format'!$B$7)) -> 30.1 | AD26: Feaster, Tavien - ARI | AH26: =AG26/AF26 -> #DIV/0! | AJ26: =AI26/AF26 -> #DIV/0! | AL26: =AN26/AM26 -> #DIV/0! | AQ26: =(AG26*0.1)+(AI26*6)+(AN26*0.1)+(AP26*6) -> 0 | AR26: =AQ26/AN26 -> #DIV/0! | AV26: =(#REF!+AM26)/(#REF!+AM32) -> #REF! | AW26: =#REF!/(AM26+#REF!) -> #REF! | AX26: =AM26/(#REF!+AM26) -> #REF! | AZ26: =(#REF!*0.1)+(AF26*6)+(AJ26*1)+(AK26*0.1)+(AM26*6) -> #REF! | BA26: =(#REF!*0.1)+(AF26*6)+(AK26*1)+(AL26*0.1)+(AN26*6) -> #REF!
A27: Total | D27: =SUM(D22:D26) -> 331 | E27: =SUM(E22:E26) -> 1332 | G27: =SUM(G22:G26) -> 10 | K27: =SUM(K22:K26) -> 118 | L27: =SUM(L22:L26) -> 87 | M27: =SUM(M22:M26) -> 651 | O27: =SUM(O22:O26) -> 3 | AD27: Total | AF27: =SUM(AF22:AF26) -> 304 | AG27: =SUM(AG22:AG26) -> 1513 | AI27: =SUM(AI22:AI26) -> 13 | AM27: =SUM(AM22:AM26) -> 98 | AN27: =SUM(AN22:AN26) -> 72 | AO27: =SUM(AO22:AO26) -> 491 | AQ27: =SUM(AQ22:AQ26) -> 4
B29: 200
A30: Receiving | K30: Rushing | S30: Touches | W30: Fantasy Points | AD30: Receiving | AM30: Rushing | AU30: Touches | AY30: Fantasy Points
A31: WRs | B31: Age | C31: G | D31: Catch % | E31: Targets | F31: Rec | G31: Yds | H31: Yds/Rec | I31: TDs | J31: TDs/Rec | L31: Ratt | M31: Ryds | N31: Ryds/Att | O31: RTds | P31: TDs/Att | S31: WRs | T31: Touch % | U31: Pct Pass | V31: Pct Run | X31: Fpts | Y31: PPR Fpts | Z31: .5PPR | AD31: WRs | AE31: G | AF31: Catch % | AG31: Targets | AH31: Rec | AI31: Yds | AJ31: Yds/Rec | AK31: TDs | AL31: TDs/Rec | AN31: Ratt | AO31: Ryds | AP31: Ryds/Att | AQ31: RTds | AR31: TDs/Att | AV31: Touch % | AW31: Pct Pass | AX31: Pct Run | AZ31: Fpts | BA31: PPR Fpts
A32: WR*Harrison, Marvin - ARI | B32: 24 | C32: 17 | D32: =F32/E32 -> 0.57575758 | E32: 99 | F32: 57 | G32: 837 | H32: =G32/F32 -> 14.684211 | I32: 6 | J32: =I32/F32 -> 0.10526316 | L32: 0 | M32: 0 | N32: =M32/L32 -> #DIV/0! | O32: 0 | P32: =O32/L32 -> #DIV/0! | S32: Harrison, Marvin | T32: =(E32+L32)/($D$27+$L$27+$N$17+$E$47+$L$47) -> 0.15420561 | U32: =E32/($E$17) -> 0.24565757 | V32: =L32/($N$17+$D$27+$L$38+$L$47) -> 0 | X32: =($G32*('Scoring Format'!$B$4))+($I32*'Scoring Format'!$B$7)+($M32*('Scoring Format'!$B$3))+($O32*('Scoring Format'!$B$6)) -> 119.7 | Y32: =(F32*1)+(($G32*('Scoring Format'!$B$4))+($I32*'Scoring Format'!$B$7)+($M32*('Scoring Format'!$B$3))+($O32*('Scoring Format'!$B$6))) -> 176.7 | Z32: =(F32*0.5)+(($G32*('Scoring Format'!$B$4))+($I32*'Scoring Format'!$B$7)+($M32*('Scoring Format'!$B$3))+($O32*('Scoring Format'!$B$6))) -> 148.2 | AD32: Green, A.J. - ARI | AF32: =AH32/AG32 -> 0.60747664 | AG32: 107 | AH32: 65 | AI32: 710 | AJ32: =AI32/AH32 -> 10.923077 | AK32: 6 | AL32: =AK32/AH32 -> 0.092307692 | AN32: 0 | AO32: 0 | AP32: =AO32/AN32 -> #DIV/0! | AQ32: 0 | AR32: =AQ32/AN32 -> #DIV/0! | AV32: =(#REF!+AK32)/(#REF!+AK35) -> #REF! | AW32: =#REF!/(AK32+#REF!) -> #REF! | AX32: =AK32/(#REF!+AK32) -> #REF! | AZ32: =(AI32*0.1)+(AK32*6)+(AO32*0.1)+(AQ32*6) -> 107 | BA32: =(AH32*1)+(AI32*0.1)+(AK32*6)+(AO32*0.1)+(AQ32*6) -> 172
A33: WR*Wilson, Michael - ARI | B33: 26 | C33: 17 | D33: =F33/E33 -> 0.65034965 | E33: 143 | F33: 93 | G33: 1270 | H33: =G33/F33 -> 13.655914 | I33: 8 | J33: =I33/F33 -> 0.086021505 | L33: 0 | M33: 0 | N33: =M33/L33 -> #DIV/0! | O33: 0 | P33: =O33/L33 -> #DIV/0! | S33: Wilson, Michael - ARI | T33: =(E33+L33)/($D$27+$L$27+$N$17+$E$47+$L$47) -> 0.22274143 | U33: =E33/($E$17) -> 0.35483871 | V33: =L33/($N$17+$D$27+$L$38+$L$47) -> 0 | X33: =($G33*('Scoring Format'!$B$4))+($I33*'Scoring Format'!$B$7)+($M33*('Scoring Format'!$B$3))+($O33*('Scoring Format'!$B$6)) -> 175 | Y33: =(F33*1)+(($G33*('Scoring Format'!$B$4))+($I33*'Scoring Format'!$B$7)+($M33*('Scoring Format'!$B$3))+($O33*('Scoring Format'!$B$6))) -> 268 | Z33: =(F33*0.5)+(($G33*('Scoring Format'!$B$4))+($I33*'Scoring Format'!$B$7)+($M33*('Scoring Format'!$B$3))+($O33*('Scoring Format'!$B$6))) -> 221.5 | AD33: Kirk, Christian- ARI | AF33: =AH33/AG33 -> 0.63333333 | AG33: 120 | AH33: 76 | AI33: 892 | AJ33: =AI33/AH33 -> 11.736842 | AK33: 5 | AL33: =AK33/AH33 -> 0.065789474 | AN33: 12 | AO33: 108 | AP33: =AO33/AN33 -> 9 | AQ33: 0 | AR33: =AQ33/AN33 -> 0 | AV33: =(#REF!+AK33)/(#REF!+AK36) -> #REF! | AW33: =#REF!/(AK33+#REF!) -> #REF! | AX33: =AK33/(#REF!+AK33) -> #REF! | AZ33: =(AI33*0.1)+(AK33*6)+(AO33*0.1)+(AQ33*6) -> 130 | BA33: =(AH33*1)+(AI33*0.1)+(AK33*6)+(AO33*0.1)+(AQ33*6) -> 206
A34: WR*Bourne, Kendrick - ARI | B34: 30 | C34: 16 | D34: =F34/E34 -> 0.68292683 | E34: 41 | F34: 28 | G34: 420 | H34: =G34/F34 -> 15 | I34: 2 | J34: =I34/F34 -> 0.071428571 | N34: =M34/L34 -> #DIV/0! | O34: 0 | P34: =O34/L34 -> #DIV/0! | S34: Bourne, Kendrick - ARI | T34: =(E34+L34)/($D$27+$L$27+$N$17+$E$47+$L$47) -> 0.063862928 | U34: =E34/($E$17) -> 0.10173697 | V34: =L34/($N$17+$D$27+$L$38+$L$47) -> 0 | X34: =($G34*('Scoring Format'!$B$4))+($I34*'Scoring Format'!$B$7)+($M34*('Scoring Format'!$B$3))+($O34*('Scoring Format'!$B$6)) -> 54 | Y34: =(F34*1)+(($G34*('Scoring Format'!$B$4))+($I34*'Scoring Format'!$B$7)+($M34*('Scoring Format'!$B$3))+($O34*('Scoring Format'!$B$6))) -> 82 | Z34: =(F34*0.5)+(($G34*('Scoring Format'!$B$4))+($I34*'Scoring Format'!$B$7)+($M34*('Scoring Format'!$B$3))+($O34*('Scoring Format'!$B$6))) -> 68 | AD34: Isabella, Andy - ARI | AF34: =AH34/AG34 -> 0.55 | AG34: 40 | AH34: 22 | AI34: 325 | AJ34: =AI34/AH34 -> 14.772727 | AK34: 2 | AL34: =AK34/AH34 -> 0.090909091 | AN34: 5 | AO34: 20 | AP34: =AO34/AN34 -> 4 | AQ34: 0 | AR34: =AQ34/AN34 -> 0 | AV34: =(#REF!+AK34)/(#REF!+AK37) -> #REF! | AW34: =#REF!/(AK34+#REF!) -> #REF! | AX34: =AK34/(#REF!+AK34) -> #REF! | AZ34: =(AI34*0.1)+(AK34*6)+(AO34*0.1)+(AQ34*6) -> 46.5 | BA34: =(AH34*1)+(AI34*0.1)+(AK34*6)+(AO34*0.1)+(AQ34*6) -> 68.5
A35: WR*Duvernay, Devin - ARI | B35: 28 | C35: 17 | D35: =F35/E35 -> 0.5 | E35: 10 | F35: 5 | G35: 60 | H35: =G35/F35 -> 12 | I35: 0 | J35: =I35/F35 -> 0 | L35: 5 | M35: 18 | N35: =M35/L35 -> 3.6 | O35: 1 | P35: =O35/L35 -> 0.2 | S35: Duvernay, Devin - ARI | T35: =(E35+L35)/($D$27+$L$27+$N$17+$E$47+$L$47) -> 0.023364486 | U35: =E35/($E$17) -> 0.024813896 | V35: =L35/($N$17+$D$27+$L$38+$L$47) -> 0.013089005 | X35: =($G35*('Scoring Format'!$B$4))+($I35*'Scoring Format'!$B$7)+($M35*('Scoring Format'!$B$3))+($O35*('Scoring Format'!$B$6)) -> 13.8 | Y35: =(F35*1)+(($G35*('Scoring Format'!$B$4))+($I35*'Scoring Format'!$B$7)+($M35*('Scoring Format'!$B$3))+($O35*('Scoring Format'!$B$6))) -> 18.8 | Z35: =(F35*0.5)+(($G35*('Scoring Format'!$B$4))+($I35*'Scoring Format'!$B$7)+($M35*('Scoring Format'!$B$3))+($O35*('Scoring Format'!$B$6))) -> 16.3 | AD35: Hopkins, DeAndre - ARI | AF35: =AH35/AG35 -> 0.66206897 | AG35: 145 | AH35: 96 | AI35: 1098 | AJ35: =AI35/AH35 -> 11.4375 | AK35: 7 | AL35: =AK35/AH35 -> 0.072916667 | AN35: 0 | AO35: 0 | AP35: =AO35/AN35 -> #DIV/0! | AQ35: 0 | AR35: =AQ35/AN35 -> #DIV/0! | AV35: =(#REF!+AK35)/(#REF!+AK38) -> #REF! | AW35: =#REF!/(AK35+#REF!) -> #REF! | AX35: =AK35/(#REF!+AK35) -> #REF! | AZ35: =(AI35*0.1)+(AK35*6)+(AO35*0.1)+(AQ35*6) -> 151.8 | BA35: =(AH35*1)+(AI35*0.1)+(AK35*6)+(AO35*0.1)+(AQ35*6) -> 247.8
A36: WR*Weaver, Xavier - ARI | B36: 23 | C36: 17 | D36: =F36/E36 -> 0 | E36: 2 | F36: 0 | G36: 0 | H36: =G36/F36 -> #DIV/0! | I36: 0 | J36: =I36/F36 -> #DIV/0! | N36: =M36/L36 -> #DIV/0! | O36: 0 | P36: =O36/L36 -> #DIV/0! | S36: Weaver, Xavier - ARI | T36: =(E36+L36)/($D$27+$L$27+$N$17+$E$47+$L$47) -> 0.0031152648 | U36: =E36/($E$17) -> 0.0049627792 | V36: =L36/($N$17+$D$27+$L$38+$L$47) -> 0 | X36: =($G36*('Scoring Format'!$B$4))+($I36*'Scoring Format'!$B$7)+($M36*('Scoring Format'!$B$3))+($O36*('Scoring Format'!$B$6)) -> 0 | Y36: =(F36*1)+(($G36*('Scoring Format'!$B$4))+($I36*'Scoring Format'!$B$7)+($M36*('Scoring Format'!$B$3))+($O36*('Scoring Format'!$B$6))) -> 0 | Z36: =(F36*0.5)+(($G36*('Scoring Format'!$B$4))+($I36*'Scoring Format'!$B$7)+($M36*('Scoring Format'!$B$3))+($O36*('Scoring Format'!$B$6))) -> 0 | AD36: Johnson, KeeSean - ARI | AF36: =AH36/AG36 -> 0.6 | AG36: 10 | AH36: 6 | AI36: 100 | AJ36: =AI36/AH36 -> 16.666667 | AK36: 0 | AL36: =AK36/AH36 -> 0 | AN36: 0 | AO36: 0 | AP36: =AO36/AN36 -> #DIV/0! | AQ36: 0 | AR36: =AQ36/AN36 -> #DIV/0! | AV36: =(#REF!+AK36)/(#REF!+AJ41) -> #REF! | AW36: =#REF!/(AK36+#REF!) -> #REF! | AX36: =AK36/(#REF!+AK36) -> #REF! | AZ36: =(AI36*0.1)+(AK36*6)+(AO36*0.1)+(AQ36*6) -> 10 | BA36: =(AH36*1)+(AI36*0.1)+(AK36*6)+(AO36*0.1)+(AQ36*6) -> 16
A37: WR*Virgil, Reggie - ARI | B37: 22 | C37: 17 | D37: =F37/E37 -> 0 | E37: 1 | F37: 0 | G37: 0 | H37: =G37/F37 -> #DIV/0! | I37: 0 | J37: =I37/F37 -> #DIV/0! | N37: =M37/L37 -> #DIV/0! | O37: 0 | P37: =O37/L37 -> #DIV/0! | S37: Virgil, Reggie - ARI | T37: =(E37+L37)/($D$27+$L$27+$N$17+$E$47+$L$47) -> 0.0015576324 | U37: =E37/($E$17) -> 0.0024813896 | V37: =L37/($N$17+$D$27+$L$38+$L$47) -> 0 | X37: =($G37*('Scoring Format'!$B$4))+($I37*'Scoring Format'!$B$7)+($M37*('Scoring Format'!$B$3))+($O37*('Scoring Format'!$B$6)) -> 0 | Y37: =(F37*1)+(($G37*('Scoring Format'!$B$4))+($I37*'Scoring Format'!$B$7)+($M37*('Scoring Format'!$B$3))+($O37*('Scoring Format'!$B$6))) -> 0 | Z37: =(F37*0.5)+(($G37*('Scoring Format'!$B$4))+($I37*'Scoring Format'!$B$7)+($M37*('Scoring Format'!$B$3))+($O37*('Scoring Format'!$B$6))) -> 0 | AD37: Moore, Rondale - ARI | AF37: =AH37/AG37 -> #DIV/0! | AL37: =AK37/AH37 -> #DIV/0! | AP37: =AO37/AN37 -> #DIV/0! | AR37: =AQ37/AN37 -> #DIV/0! | AV37: =(#REF!+AK37)/(#REF!+AK42) -> #REF! | AW37: =#REF!/(AK37+#REF!) -> #REF! | AX37: =AK37/(#REF!+AK37) -> #REF!
A38: Total | E38: =SUM(E32:E37) -> 296 | F38: =SUM(F32:F37) -> 183 | G38: =SUM(G32:G37) -> 2587 | I38: =SUM(I32:I37) -> 16 | L38: =SUM(L32:L37) -> 5 | M38: =SUM(M32:M37) -> 18 | O38: =SUM(O32:O37) -> 1 | AD38: Total | AG38: =SUM(AG32:AG37) -> 422 | AH38: =SUM(AH32:AH37) -> 265 | AI38: =SUM(AI32:AI37) -> 3125 | AK38: =SUM(AK32:AK37) -> 20 | AN38: =SUM(AN32:AN37) -> 17 | AO38: =SUM(AO32:AO37) -> 128 | AQ38: =SUM(AQ32:AQ37) -> 0
S39: Weaver, Xavier - ARI
A41: Receiving | K41: Rushing | S41: Touches | W41: Fantasy Points | AD41: Receiving | AM41: Rushing | AU41: Touches | AY41: Fantasy Points
A42: Tes | B42: Age | C42: G | D42: Catch % | E42: Targets | F42: Rec | G42: Yds | H42: Yds/Rec | I42: TDs | J42: TDs/Rec | L42: Ratt | M42: Ryds | N42: Ryds/Att | O42: RTDs | P42: TDs/Att | S42: Tes | T42: Touch % | U42: Pct Pass | V42: Pct Run | X42: Fpts | Y42: PPR Fpts | Z42: .5 PPR | AD42: Tes | AE42: G | AF42: Catch % | AG42: Targets | AH42: Rec | AI42: Yds | AJ42: Yds/Rec | AK42: TDs | AL42: TDs/Rec | AN42: Ratt | AO42: Ryds | AP42: Ryds/Att | AQ42: RTDs | AR42: TDs/Att | AV42: Touch % | AW42: Pct Pass | AX42: Pct Run | AZ42: Fpts | BA42: PPR Fpts
A43: TE*McBride, Trey - ARI | B43: 26 | C43: 17 | D43: =F43/E43 -> 0.75316456 | E43: 158 | F43: 119 | G43: 1193 | H43: =G43/F43 -> 10.02521 | I43: 8 | J43: =I43/F43 -> 0.067226891 | L43: 0 | M43: 0 | N43: 0 | O43: 0 | P43: =O43/L43 -> #DIV/0! | S43: McBride, Trey - ARI | T43: =(E43+L43)/($E$47+$L$47+$E$38+$L$38+$K$27+$D$27+$N$17) -> 0.16221766 | U43: =E43/($E$47+$E$38+$K$27) -> 0.26689189 | V43: =L43/($L$47+$L$38+$D$27+$N$17) -> 0 | X43: =($G43*('Scoring Format'!$B$4))+($I43*'Scoring Format'!$B$7)+($M43*('Scoring Format'!$B$3))+($O43*('Scoring Format'!$B$6)) -> 167.3 | Y43: =(F43*1)+(($G43*('Scoring Format'!$B$4))+($I43*'Scoring Format'!$B$7)+($M43*('Scoring Format'!$B$3))+($O43*('Scoring Format'!$B$6))) -> 286.3 | Z43: =(F43*0.5)+(($G43*('Scoring Format'!$B$4))+($I43*'Scoring Format'!$B$7)+($M43*('Scoring Format'!$B$3))+($O43*('Scoring Format'!$B$6))) -> 226.8 | AD43: Williams, Maxx - ARI | AF43: =AH43/AG43 -> 0.5625 | AG43: 16 | AH43: 9 | AI43: 108 | AJ43: =AI43/AH43 -> 12 | AK43: 1 | AL43: =AK43/AH43 -> 0.11111111 | AN43: 0 | AO43: 0 | AP43: 0 | AQ43: 0 | AR43: =AQ43/AN43 -> #DIV/0! | AV43: =(#REF!+AK43)/(#REF!+AK46) -> #REF! | AW43: =#REF!/(AK43+#REF!) -> #REF! | AX43: =AK43/(#REF!+AK43) -> #REF! | AZ43: =(AI43*0.1)+(AK43*6)+(AO43*0.1)+(AQ43*6) -> 16.8 | BA43: =(AH43*1)+(AI43*0.1)+(AK43*6)+(AO43*0.1)+(AQ43*6) -> 25.8
A44: TE*Higgins, Elijah - ARI | B44: 26 | C44: 17 | D44: =F44/E44 -> 0.8 | E44: 10 | F44: 8 | G44: 72 | H44: =G44/F44 -> 9 | I44: 0 | J44: =I44/F44 -> 0 | L44: 0 | M44: 0 | N44: 0 | O44: 0 | P44: =O44/L44 -> #DIV/0! | S44: Higgins, Elijah - ARI | T44: =(E44+L44)/($E$47+$L$47+$E$38+$L$38+$K$27+$D$27+$N$17) -> 0.01026694 | U44: =E44/($E$47+$E$38+$K$27) -> 0.016891892 | V44: =L44/($L$47+$L$38+$D$27+$N$17) -> 0 | X44: =($G44*('Scoring Format'!$B$4))+($I44*'Scoring Format'!$B$7)+($M44*('Scoring Format'!$B$3))+($O44*('Scoring Format'!$B$6)) -> 7.2 | Y44: =(F44*1)+(($G44*('Scoring Format'!$B$4))+($I44*'Scoring Format'!$B$7)+($M44*('Scoring Format'!$B$3))+($O44*('Scoring Format'!$B$6))) -> 15.2 | Z44: =(F44*0.5)+(($G44*('Scoring Format'!$B$4))+($I44*'Scoring Format'!$B$7)+($M44*('Scoring Format'!$B$3))+($O44*('Scoring Format'!$B$6))) -> 11.2 | AD44: Daniels, Darenell - ARI | AF44: =AH44/AG44 -> 0.74285714 | AG44: 35 | AH44: 26 | AI44: 283 | AJ44: =AI44/AH44 -> 10.884615 | AK44: 2 | AL44: =AK44/AH44 -> 0.076923077 | AN44: 0 | AO44: 0 | AP44: 0 | AQ44: 0 | AR44: =AQ44/AN44 -> #DIV/0! | AV44: =(#REF!+AK44)/(#REF!+AK47) -> #REF! | AW44: =#REF!/(AK44+#REF!) -> #REF! | AX44: =AK44/(#REF!+AK44) -> #REF! | AZ44: =(AI44*0.1)+(AK44*6)+(AO44*0.1)+(AQ44*6) -> 40.3 | BA44: =(AH44*1)+(AI44*0.1)+(AK44*6)+(AO44*0.1)+(AQ44*6) -> 66.3
A45: TE*Reiman, Tip - ARI | B45: 25 | C45: 17 | D45: =F45/E45 -> 0.6 | E45: 10 | F45: 6 | G45: 39 | H45: =G45/F45 -> 6.5 | I45: 1 | J45: =I45/F45 -> 0.16666667 | L45: 0 | M45: 0 | N45: 0 | O45: 0 | P45: =O45/L45 -> #DIV/0! | S45: Reiman, Tip - ARI | T45: =(E45+L45)/($E$47+$L$47+$E$38+$L$38+$K$27+$D$27+$N$17) -> 0.01026694 | U45: =E45/($E$47+$E$38+$K$27) -> 0.016891892 | V45: =L45/($L$47+$L$38+$D$27+$N$17) -> 0 | X45: =($G45*('Scoring Format'!$B$4))+($I45*'Scoring Format'!$B$7)+($M45*('Scoring Format'!$B$3))+($O45*('Scoring Format'!$B$6)) -> 9.9 | Y45: =(F45*1)+(($G45*('Scoring Format'!$B$4))+($I45*'Scoring Format'!$B$7)+($M45*('Scoring Format'!$B$3))+($O45*('Scoring Format'!$B$6))) -> 15.9 | Z45: =(F45*0.5)+(($G45*('Scoring Format'!$B$4))+($I45*'Scoring Format'!$B$7)+($M45*('Scoring Format'!$B$3))+($O45*('Scoring Format'!$B$6))) -> 12.9 | AD45: Bunting, Ian - ARI | AF45: =AH45/AG45 -> 0.5 | AG45: 12 | AH45: 6 | AI45: 65 | AJ45: =AI45/AH45 -> 10.833333 | AK45: 0 | AL45: =AK45/AH45 -> 0 | AN45: 0 | AO45: 0 | AP45: 0 | AQ45: 0 | AR45: =AQ45/AN45 -> #DIV/0! | AV45: =(#REF!+AK45)/(#REF!+AJ49) -> #REF! | AW45: =#REF!/(AK45+#REF!) -> #REF! | AX45: =AK45/(#REF!+AK45) -> #REF! | AZ45: =(AI45*0.1)+(AK45*6)+(AO45*0.1)+(AQ45*6) -> 6.5 | BA45: =(AH45*1)+(AI45*0.1)+(AK45*6)+(AO45*0.1)+(AQ45*6) -> 12.5
A46: TE*Quitoriano, Teegan - ARI | B46: 26 | D46: =F46/E46 -> #DIV/0! | H46: =G46/F46 -> #DIV/0! | I46: 0 | J46: =I46/F46 -> #DIV/0! | L46: 0 | M46: 0 | N46: 0 | O46: 0 | P46: =O46/L46 -> #DIV/0! | S46: Quitoriano, Teegan - ARI | T46: =(E46+L46)/($E$47+$L$47+$E$38+$L$38+$K$27+$D$27+$N$17) -> 0 | U46: =E46/($E$47+$E$38+$K$27) -> 0 | V46: =L46/($L$47+$L$38+$D$27+$N$17) -> 0 | X46: =($G46*('Scoring Format'!$B$4))+($I46*'Scoring Format'!$B$7)+($M46*('Scoring Format'!$B$3))+($O46*('Scoring Format'!$B$6)) -> 0 | Y46: =(F46*1)+(($G46*('Scoring Format'!$B$4))+($I46*'Scoring Format'!$B$7)+($M46*('Scoring Format'!$B$3))+($O46*('Scoring Format'!$B$6))) -> 0 | Z46: =(F46*0.5)+(($G46*('Scoring Format'!$B$4))+($I46*'Scoring Format'!$B$7)+($M46*('Scoring Format'!$B$3))+($O46*('Scoring Format'!$B$6))) -> 0 | AF46: =AH46/AG46 -> #DIV/0! | AJ46: =AI46/AH46 -> #DIV/0! | AL46: =AK46/AH46 -> #DIV/0! | AQ46: 0 | AR46: =AQ46/AN46 -> #DIV/0! | AV46: =(#REF!+AK46)/(#REF!+AJ50) -> #REF! | AW46: =#REF!/(AK46+#REF!) -> #REF! | AX46: =AK46/(#REF!+AK46) -> #REF! | AZ46: =(AI46*0.1)+(AK46*6)+(AO46*0.1)+(AQ46*6) -> 0 | BA46: =(AH46*1)+(AI46*0.1)+(AK46*6)+(AO46*0.1)+(AQ46*6) -> 0
A47: Total | E47: =SUM(E43:E46) -> 178 | F47: =SUM(F43:F46) -> 133 | G47: =SUM(G43:G46) -> 1304 | I47: =SUM(I43:I46) -> 9 | L47: =SUM(L43:L46) -> 0 | M47: =SUM(M43:M46) -> 0 | O47: =SUM(O43:O46) -> 0 | AD47: Total | AG47: =SUM(AG43:AG46) -> 63 | AH47: =SUM(AH43:AH46) -> 41 | AI47: =SUM(AI43:AI46) -> 456 | AK47: =SUM(AK43:AK46) -> 3 | AN47: =SUM(AN43:AN46) -> 0 | AO47: =SUM(AO43:AO46) -> 0 | AQ47: =SUM(AQ43:AQ46) -> 0
A50: Team Totals and Splits | K50: Taxi Squad* | S50: Injured Reserve | AD50: Team Totals and Splits | AM50: Taxi Squad* | AU50: Injured Reserve
B51: Targets | C51: Rec. | D51: Yds | E51: TDs | J51: Player | N51: Position | R51: Player | V51: Position | AD51: Targets | AE51: Rec. | AF51: Yds | AG51: TDs | AL51: Player | AP51: Position | AT51: Player | AX51: Position
...

Sheet ATL
A1: Atlanta Falcons
A3: Team Projections Menu | AD3: Team Projections Menu
I5: RSP Projections: Year 1 | N5: Adjustable Projections: Year 1 | T5: Offense Distribution | AK5: RSP Projections: Year 1 | AP5: Adjustable Projections: Year 1
I6: RSP Projections: Year 2 | N6: Past Run/Pass Performances | T6: Run | U6: Pass | AK6: RSP Projections: Year 2
T7: =(N17+D27+L38+L47)/(N17+D27+L38+D17) -> 0.47104247 | U7: =D17/(D17+N17+D27+L38+L47) -> 0.52895753
T8: Drop 2-4 percent
A10: RSP Projections: Year 1 | AD10: Adjustable Projections: Year 1
D12: Passing | M12: Rushing | S12: Touches | W12: Fantasy Points | AF12: Passing | AO12: Rushing | AU12: Touches | AY12: Fantasy Points
A13: QB | B13: Age | C13: G | D13: Att | E13: Comp | F13: Pct | G13: Yards | H13: Yds/Att | I13: TDs | J13: TDs/Att | K13: Int | L13: Int/Att | N13: Ratt | O13: Ryds | P13: Ryds/Att | Q13: TDs | R13: Tds/Att | T13: Touch % | U13: Pct Pass | V13: Pct Run | X13: Fpts | Y13: Adjusted | AD13: QB | AE13: G | AF13: Att | AG13: Comp | AH13: Pct | AI13: Yards | AJ13: Yds/Att | AK13: TDs | AL13: TDs/Att | AM13: Int | AN13: Int/Att | AP13: Ratt | AQ13: Ryds | AR13: Ryds/Att | AS13: TDs | AT13: Tds/Att | AV13: Touch % | AW13: Pct Pass | AX13: Pct Run | AZ13: Fpts | BA13: Adjusted
A14: QB*Tagovailoa, Tua - ATL | B14: 28 | C14: 9 | D14: 274 | E14: 190 | F14: =E14/D14 -> 0.69343066 | G14: 1922 | H14: =G14/D14 -> 7.0145985 | I14: 11 | J14: =I14/D14 -> 0.040145985 | K14: 8 | L14: =K14/D14 -> 0.02919708 | N14: 12 | O14: 24 | P14: =O14/N14 -> 2 | Q14: 0 | R14: =Q14/N14 -> 0 | T14: =(D14+N14)/($D$17+$N$17) -> 0.48639456 | U14: =D14/($D$17) -> 0.5 | V14: =N14/($N$17) -> 0.3 | X14: =($G14*('Scoring Format'!$B$2))+($I14*('Scoring Format'!$B$5))+($K14*('Scoring Format'!$B$8))+($O14*('Scoring Format'!$B$3))+($Q14*('Scoring Format'!$B$6)) -> 134.5 | Y14: =(($G14*('Scoring Format'!$B$2))+($I14*('Scoring Format'!$B$5))+($K14*('Scoring Format'!$B$8))+($O14*('Scoring Format'!$B$3))+($Q14*('Scoring Format'!$B$6)))*0.4 -> 53.8 | AD14: Murray, Kyler - ARI | AF14: 583 | AG14: 378 | AH14: =AG14/AF14 -> 0.6483705 | AI14: 4072 | AJ14: =AI14/AF14 -> 6.9845626 | AK14: 27 | AL14: =AK14/AF14 -> 0.046312178 | AM14: 11 | AN14: =AM14/AF14 -> 0.018867925 | AP14: 100 | AQ14: 590 | AR14: =AQ14/AP14 -> 5.9 | AS14: 5 | AT14: =AS14/AP14 -> 0.05 | AV14: =(AF14+AP14)/(AF17+AP17) -> 1 | AW14: =AF14/(AP14+AF14) -> 0.85358712 | AX14: =AP14/(AF14+AP14) -> 0.14641288 | AZ14: =((AI14*0.05)+(AK14*4)+(AM14*-1)+(AQ14*0.1)+(AS14*6))*0.55 -> 214.28 | BA14: =((AI14*0.05)+(AK14*4)+(AM14*-1)+(AQ14*0.1)+(AS14*6))*0.4 -> 155.84
A15: QB*Siemian, Trevor - ATL | B15: 34 | C15: 0 | F15: =E15/D15 -> #DIV/0! | H15: =G15/D15 -> #DIV/0! | J15: =I15/D15 -> #DIV/0! | L15: =K15/D15 -> #DIV/0! | P15: =O15/N15 -> #DIV/0! | Q15: 0 | R15: =Q15/N15 -> #DIV/0! | T15: =(D15+N15)/($D$17+$N$17) -> 0 | U15: =D15/($D$17) -> 0 | V15: =N15/($N$17) -> 0 | X15: =($G15*('Scoring Format'!$B$2))+($I15*('Scoring Format'!$B$5))+($K15*('Scoring Format'!$B$8))+($O15*('Scoring Format'!$B$3))+($Q15*('Scoring Format'!$B$6)) -> 0 | Y15: =(($G15*('Scoring Format'!$B$2))+($I15*('Scoring Format'!$B$5))+($K15*('Scoring Format'!$B$8))+($O15*('Scoring Format'!$B$3))+($Q15*('Scoring Format'!$B$6)))*0.4 -> 0 | AD15: McCoy, Colt - ARI | AF15: 0 | AG15: 0 | AH15: 0 | AI15: 0 | AK15: 0 | AL15: =AK15/AF15 -> #DIV/0! | AM15: 0 | AN15: =AM15/AF15 -> #DIV/0! | AP15: 0 | AQ15: 0 | AS15: 0 | AT15: =AS15/AP15 -> #DIV/0! | AV15: =(AF15+AP15)/(AE18+AO18) -> #DIV/0! | AW15: =AF15/(AP15+AF15) -> #DIV/0! | AX15: =AP15/(AF15+AP15) -> #DIV/0!
A16: QB*Penix, Michael - ATL | B16: 26 | C16: 8 | D16: 274 | E16: 175 | F16: =E16/D16 -> 0.63868613 | G16: 2042 | H16: =G16/D16 -> 7.4525547 | I16: 13 | J16: =I16/D16 -> 0.047445255 | K16: 6 | L16: =K16/D16 -> 0.02189781 | N16: 28 | O16: 56 | P16: =O16/N16 -> 2 | Q16: 0 | R16: =Q16/N16 -> 0 | T16: =(D16+N16)/($D$17+$N$17) -> 0.51360544 | U16: =D16/($D$17) -> 0.5 | V16: =N16/($N$17) -> 0.7 | X16: =($G16*('Scoring Format'!$B$2))+($I16*('Scoring Format'!$B$5))+($K16*('Scoring Format'!$B$8))+($O16*('Scoring Format'!$B$3))+($Q16*('Scoring Format'!$B$6)) -> 153.7 | Y16: =(($G16*('Scoring Format'!$B$2))+($I16*('Scoring Format'!$B$5))+($K16*('Scoring Format'!$B$8))+($O16*('Scoring Format'!$B$3))+($Q16*('Scoring Format'!$B$6)))*0.4 -> 61.48 | AD16: McDonald, Cole - ARI | AH16: =AG16/AF16 -> #DIV/0! | AJ16: =AI16/AF16 -> #DIV/0! | AL16: =AK16/AF16 -> #DIV/0! | AN16: =AM16/AF16 -> #DIV/0! | AR16: =AQ16/AP16 -> #DIV/0! | AT16: =AS16/AP16 -> #DIV/0! | AV16: =(AF16+AP16)/(AE20+AO20) -> #DIV/0! | AW16: =AF16/(AP16+AF16) -> #DIV/0! | AX16: =AP16/(AF16+AP16) -> #DIV/0! | AZ16: =((AI16*0.05)+(AK16*4)+(AM16*-1)+(AQ16*0.1)+(AS16*6))*0.55 -> 0 | BA16: =((AI16*0.05)+(AK16*4)+(AM16*-1)+(AQ16*0.1)+(AS16*6))*0.4 -> 0
A17: Total | D17: =SUM(D14:D16) -> 548 | E17: =SUM(E14:E16) -> 365 | G17: =SUM(G14:G16) -> 3964 | I17: =SUM(I14:I16) -> 24 | K17: =SUM(K14:K16) -> 14 | N17: =SUM(N14:N16) -> 40 | O17: =SUM(O14:O16) -> 80 | Q17: =SUM(Q14:Q16) -> 0 | T17: =T14+T15+T16 -> 1 | U17: =D17/(D17+N17) -> 0.93197279 | V17: =N17/(N17+D17) -> 0.068027211 | AD17: Total | AF17: =SUM(AF14:AF16) -> 583 | AG17: =SUM(AG14:AG16) -> 378 | AI17: =SUM(AI14:AI16) -> 4072 | AK17: =SUM(AK14:AK16) -> 27 | AM17: =SUM(AM14:AM16) -> 11 | AP17: =SUM(AP14:AP16) -> 100 | AQ17: =SUM(AQ14:AQ16) -> 590 | AS17: =SUM(AS14:AS16) -> 5 | AV17: =AV14+AV15+AV16 -> #DIV/0! | AW17: =AF17/(AF17+AP17) -> 0.85358712 | AX17: =AP17/(AP17+AF17) -> 0.14641288
A20: Rushing | I20: Receiving | S20: Touches | W20: Fantasy Points | AD20: Rushing | AK20: Receiving | AU20: Touches | AY20: Fantasy Points
A21: RB | B21: Age | C21: G | D21: Att | E21: Yards | F21: Yds/Att | G21: TDs | H21: TDs/Att | J21: Catch % | K21: Targets | L21: Rec | M21: Yds | N21: Yds/Rec | O21: TDs | P21: TDs/Rec | S21: RB | T21: Touch % | U21: Pct Pass | V21: Pct Run | X21: Fpts | Y21: PPR Fpts | Z21: .5 PPR | AD21: RB | AE21: G | AF21: Att | AG21: Yards | AH21: Yds/Att | AI21: TDs | AJ21: TDs/Att | AL21: Catch % | AM21: Targets | AN21: Rec | AO21: Yds | AP21: Yds/Rec | AQ21: TDs | AR21: TDs/Rec | AV21: Touch % | AW21: Pct Pass | AX21: Pct Run | AZ21: Fpts | BA21: PPR Fpts
A22: RB*Robinson, Bijan - ATL | B22: 26 | C22: 17 | D22: 295 | E22: 1466 | F22: =E22/D22 -> 4.9694915 | G22: 11 | H22: =G22/D22 -> 0.037288136 | J22: =L22/K22 -> 0.79545455 | K22: 88 | L22: 70 | M22: 625 | N22: =M22/L22 -> 8.9285714 | O22: 3 | P22: =O22/L22 -> 0.042857143 | S22: Robinson, Bijan - ATL | T22: =(D22+K22)/($D$27+$K$27+$N$17+$E$17+$L$38+$L$47) -> 0.39484536 | U22: =K22/($K$27+$F$38+$F$47) -> 0.22564103 | V22: =D22/($D$27+$N$17+$L$38+$L$47) -> 0.6045082 | X22: =($E22*('Scoring Format'!$B$3))+($G22*('Scoring Format'!$B$6))+($M22*('Scoring Format'!$B$4))+($O22*('Scoring Format'!$B$7)) -> 293.1 | Y22: =($E22*('Scoring Format'!$B$3))+($G22*('Scoring Format'!$B$6))+(L22*1)+($M22*('Scoring Format'!$B$4))+($O22*('Scoring Format'!$B$7)) -> 363.1 | Z22: =($E22*('Scoring Format'!$B$3))+($G22*('Scoring Format'!$B$6))+(L22*0.5)+($M22*('Scoring Format'!$B$4))+($O22*('Scoring Format'!$B$7)) -> 328.1 | AD22: Conner, James - ARI | AF22: 200 | AG22: 1040 | AH22: =AG22/AF22 -> 5.2 | AI22: 7 | AJ22: =AI22/AF22 -> 0.035 | AL22: =AN22/AM22 -> 0.8 | AM22: 70 | AN22: 56 | AO22: 364 | AP22: =AO22/AN22 -> 6.5 | AQ22: 2 | AR22: =AQ22/AN22 -> 0.035714286 | AV22: =(#REF!+AM22)/(#REF!+AM25) -> #REF! | AW22: =#REF!/(AM22+#REF!) -> #REF! | AX22: =AM22/(#REF!+AM22) -> #REF! | AZ22: =(#REF!*0.1)+(AF22*6)+(AL22*0.1)+(AN22*6) -> #REF! | BA22: =(#REF!*0.1)+(AF22*6)+(AK22*1)+(AL22*0.1)+(AN22*6) -> #REF!
A23: RB*Robinson, Brian - ATL | B23: 27 | C23: 17 | D23: 140 | E23: 579 | F23: =E23/D23 -> 4.1357143 | G23: 3 | H23: =G23/D23 -> 0.021428571 | J23: =L23/K23 -> 0.77272727 | K23: 22 | L23: 17 | M23: 116 | N23: =M23/L23 -> 6.8235294 | O23: 0 | P23: =O23/L23 -> 0 | S23: Robinson, Brian - ATL | T23: =(D23+K23)/($D$27+$K$27+$N$17+$E$17+$L$38+$L$47) -> 0.16701031 | U23: =K23/($K$27+$F$38+$F$47) -> 0.056410256 | V23: =D23/($D$27+$N$17+$L$38+$L$47) -> 0.28688525 | X23: =($E23*('Scoring Format'!$B$3))+($G23*('Scoring Format'!$B$6))+($M23*('Scoring Format'!$B$4))+($O23*('Scoring Format'!$B$7)) -> 87.5 | Y23: =($E23*('Scoring Format'!$B$3))+($G23*('Scoring Format'!$B$6))+(L23*1)+($M23*('Scoring Format'!$B$4))+($O23*('Scoring Format'!$B$7)) -> 104.5 | Z23: =($E23*('Scoring Format'!$B$3))+($G23*('Scoring Format'!$B$6))+(L23*0.5)+($M23*('Scoring Format'!$B$4))+($O23*('Scoring Format'!$B$7)) -> 96 | AD23: Edmonds, Chase - ARI | AF23: 96 | AG23: 445 | AH23: =AG23/AF23 -> 4.6354167 | AI23: 6 | AJ23: =AI23/AF23 -> 0.0625 | AL23: =AN23/AM23 -> 0.58333333 | AM23: 24 | AN23: 14 | AO23: 110 | AP23: =AO23/AN23 -> 7.8571429 | AQ23: 2 | AR23: =AQ23/AN23 -> 0.14285714 | AV23: =(#REF!+AM23)/(#REF!+AM26) -> #REF! | AW23: =#REF!/(AM23+#REF!) -> #REF! | AX23: =AM23/(#REF!+AM23) -> #REF! | AZ23: =(#REF!*0.1)+(AF23*6)+(AL23*0.1)+(AN23*6) -> #REF! | BA23: =(#REF!*0.1)+(AF23*6)+(AK23*1)+(AL23*0.1)+(AN23*6) -> #REF!
A24: RB*Goodson, Tyler - ATL | B24: 25 | C24: 17 | D24: 10 | E24: 57 | F24: =E24/D24 -> 5.7 | G24: 1 | H24: =G24/D24 -> 0.1 | J24: =L24/K24 -> 0.71428571 | K24: 7 | L24: 5 | M24: 30 | N24: =M24/L24 -> 6 | O24: 0 | P24: =O24/L24 -> 0 | S24: Goodson, Tyler - ATL | T24: =(D24+K24)/($D$27+$K$27+$N$17+$E$17+$L$38+$L$47) -> 0.017525773 | U24: =K24/($K$27+$F$38+$F$47) -> 0.017948718 | V24: =D24/($D$27+$N$17+$L$38+$L$47) -> 0.020491803 | X24: =($E24*('Scoring Format'!$B$3))+($G24*('Scoring Format'!$B$6))+($M24*('Scoring Format'!$B$4))+($O24*('Scoring Format'!$B$7)) -> 14.7 | Y24: =($E24*('Scoring Format'!$B$3))+($G24*('Scoring Format'!$B$6))+(L24*1)+($M24*('Scoring Format'!$B$4))+($O24*('Scoring Format'!$B$7)) -> 19.7 | Z24: =($E24*('Scoring Format'!$B$3))+($G24*('Scoring Format'!$B$6))+(L24*0.5)+($M24*('Scoring Format'!$B$4))+($O24*('Scoring Format'!$B$7)) -> 17.2 | AD24: Benjamin, Eno - ARI | AF24: 8 | AG24: 28 | AH24: =AG24/AF24 -> 3.5 | AI24: 0 | AJ24: =AI24/AF24 -> 0 | AL24: =AN24/AM24 -> 0.5 | AM24: 4 | AN24: 2 | AO24: 17 | AP24: =AO24/AN24 -> 8.5 | AQ24: 0 | AR24: =AQ24/AN24 -> 0 | AV24: =(#REF!+AM24)/(#REF!+AL30) -> #REF! | AW24: =#REF!/(AM24+#REF!) -> #REF! | AX24: =AM24/(#REF!+AM24) -> #REF! | AZ24: =(#REF!*0.1)+(AF24*6)+(AL24*0.1)+(AN24*6) -> #REF! | BA24: =(#REF!*0.1)+(AF24*6)+(AK24*1)+(AL24*0.1)+(AN24*6) -> #REF!
F25: =E25/D25 -> #DIV/0! | G25: 0 | H25: =G25/D25 -> #DIV/0! | J25: =L25/K25 -> #DIV/0! | N25: =M25/L25 -> #DIV/0! | O25: 0 | P25: =O25/L25 -> #DIV/0! | T25: =(D25+K25)/($D$27+$K$27+$N$17+$E$17+$L$38+$L$47) -> 0 | U25: =K25/($K$27+$F$38+$F$47) -> 0 | V25: =D25/($D$27+$N$17+$L$38+$L$47) -> 0 | X25: =($E25*('Scoring Format'!$B$3))+($G25*('Scoring Format'!$B$6))+($M25*('Scoring Format'!$B$4))+($O25*('Scoring Format'!$B$7)) -> 0 | Y25: =($E25*('Scoring Format'!$B$3))+($G25*('Scoring Format'!$B$6))+(L25*1)+($M25*('Scoring Format'!$B$4))+($O25*('Scoring Format'!$B$7)) -> 0 | Z25: =($E25*('Scoring Format'!$B$3))+($G25*('Scoring Format'!$B$6))+(L25*0.5)+($M25*('Scoring Format'!$B$4))+($O25*('Scoring Format'!$B$7)) -> 0 | AD25: Ward, Jonathan - ARI | AH25: =AG25/AF25 -> #DIV/0! | AI25: 0 | AJ25: =AI25/AF25 -> #DIV/0! | AL25: =AN25/AM25 -> #DIV/0! | AP25: =AO25/AN25 -> #DIV/0! | AQ25: 0 | AR25: =AQ25/AN25 -> #DIV/0! | AV25: =(#REF!+AM25)/(#REF!+AM31) -> #REF! | AW25: =#REF!/(AM25+#REF!) -> #REF! | AX25: =AM25/(#REF!+AM25) -> #REF! | AZ25: =(#REF!*0.1)+(AF25*6)+(AL25*0.1)+(AN25*6) -> #REF! | BA25: =(#REF!*0.1)+(AF25*6)+(AK25*1)+(AL25*0.1)+(AN25*6) -> #REF!
F26: =E26/D26 -> #DIV/0! | G26: 0 | H26: =G26/D26 -> #DIV/0! | J26: =L26/K26 -> #DIV/0! | N26: =M26/L26 -> #DIV/0! | O26: 0 | P26: =O26/L26 -> #DIV/0! | T26: =(D26+K26)/($D$27+$K$27+$N$17+$E$17+$L$38+$L$47) -> 0 | U26: =K26/($K$27+$F$38+$F$47) -> 0 | V26: =D26/($D$27+$N$17+$L$38+$L$47) -> 0 | X26: =($E26*('Scoring Format'!$B$3))+($G26*('Scoring Format'!$B$6))+($M26*('Scoring Format'!$B$4))+($O26*('Scoring Format'!$B$7)) -> 0 | Y26: =($E26*('Scoring Format'!$B$3))+($G26*('Scoring Format'!$B$6))+(L26*1)+($M26*('Scoring Format'!$B$4))+($O26*('Scoring Format'!$B$7)) -> 0 | Z26: =($E26*('Scoring Format'!$B$3))+($G26*('Scoring Format'!$B$6))+(L26*0.5)+($M26*('Scoring Format'!$B$4))+($O26*('Scoring Format'!$B$7)) -> 0 | AD26: Muhammad, Khalfani - ARI | AH26: =AG26/AF26 -> #DIV/0! | AJ26: =AI26/AF26 -> #DIV/0! | AL26: =AN26/AM26 -> #DIV/0! | AQ26: =(AG26*0.1)+(AI26*6)+(AN26*0.1)+(AP26*6) -> 0 | AR26: =AQ26/AN26 -> #DIV/0! | AV26: =(#REF!+AM26)/(#REF!+AM32) -> #REF! | AW26: =#REF!/(AM26+#REF!) -> #REF! | AX26: =AM26/(#REF!+AM26) -> #REF! | AZ26: =(#REF!*0.1)+(AF26*6)+(AJ26*1)+(AK26*0.1)+(AM26*6) -> #REF! | BA26: =(#REF!*0.1)+(AF26*6)+(AK26*1)+(AL26*0.1)+(AN26*6) -> #REF!
A27: Total | D27: =SUM(D22:D26) -> 445 | E27: =SUM(E22:E26) -> 2102 | G27: =SUM(G22:G26) -> 15 | K27: =SUM(K22:K26) -> 117 | L27: =SUM(L22:L26) -> 92 | M27: =SUM(M22:M26) -> 771 | O27: =SUM(O22:O26) -> 3 | AD27: Total | AF27: =SUM(AF22:AF26) -> 304 | AG27: =SUM(AG22:AG26) -> 1513 | AI27: =SUM(AI22:AI26) -> 13 | AM27: =SUM(AM22:AM26) -> 98 | AN27: =SUM(AN22:AN26) -> 72 | AO27: =SUM(AO22:AO26) -> 491 | AQ27: =SUM(AQ22:AQ26) -> 4
A30: Receiving | K30: Rushing | S30: Touches | W30: Fantasy Points | AD30: Receiving | AM30: Rushing | AU30: Touches | AY30: Fantasy Points
A31: WRs | B31: Age | C31: G | D31: Catch % | E31: Targets | F31: Rec | G31: Yds | H31: Yds/Rec | I31: TDs | J31: TDs/Rec | L31: Ratt | M31: Ryds | N31: Ryds/Att | O31: RTds | P31: TDs/Att | S31: WRs | T31: Touch % | U31: Pct Pass | V31: Pct Run | X31: Fpts | Y31: PPR Fpts | Z31: .5PPR | AD31: WRs | AE31: G | AF31: Catch % | AG31: Targets | AH31: Rec | AI31: Yds | AJ31: Yds/Rec | AK31: TDs | AL31: TDs/Rec | AN31: Ratt | AO31: Ryds | AP31: Ryds/Att | AQ31: RTds | AR31: TDs/Att | AV31: Touch % | AW31: Pct Pass | AX31: Pct Run | AZ31: Fpts | BA31: PPR Fpts
A32: WR*London, Drake - ATL | B32: 24 | C32: 17 | D32: =F32/E32 -> 0.60377358 | E32: 159 | F32: 96 | G32: 1300 | H32: =G32/F32 -> 13.541667 | I32: 10 | J32: =I32/F32 -> 0.10416667 | L32: 0 | M32: 0 | N32: =M32/L32 -> #DIV/0! | O32: 0 | P32: =O32/L32 -> #DIV/0! | S32: London, Drake - ATL | T32: =(E32+L32)/($D$27+$L$27+$N$17+$E$47+$L$47) -> 0.21285141 | U32: =E32/($E$17) -> 0.43561644 | V32: =L32/($N$17+$D$27+$L$38+$L$47) -> 0 | X32: =($G32*('Scoring Format'!$B$4))+($I32*'Scoring Format'!$B$7)+($M32*('Scoring Format'!$B$3))+($O32*('Scoring Format'!$B$6)) -> 190 | Y32: =(F32*1)+(($G32*('Scoring Format'!$B$4))+($I32*'Scoring Format'!$B$7)+($M32*('Scoring Format'!$B$3))+($O32*('Scoring Format'!$B$6))) -> 286 | Z32: =(F32*0.5)+(($G32*('Scoring Format'!$B$4))+($I32*'Scoring Format'!$B$7)+($M32*('Scoring Format'!$B$3))+($O32*('Scoring Format'!$B$6))) -> 238 | AD32: Green, A.J. - ARI | AF32: =AH32/AG32 -> 0.60747664 | AG32: 107 | AH32: 65 | AI32: 710 | AJ32: =AI32/AH32 -> 10.923077 | AK32: 6 | AL32: =AK32/AH32 -> 0.092307692 | AN32: 0 | AO32: 0 | AP32: =AO32/AN32 -> #DIV/0! | AQ32: 0 | AR32: =AQ32/AN32 -> #DIV/0! | AV32: =(#REF!+AK32)/(#REF!+AK35) -> #REF! | AW32: =#REF!/(AK32+#REF!) -> #REF! | AX32: =AK32/(#REF!+AK32) -> #REF! | AZ32: =(AI32*0.1)+(AK32*6)+(AO32*0.1)+(AQ32*6) -> 107 | BA32: =(AH32*1)+(AI32*0.1)+(AK32*6)+(AO32*0.1)+(AQ32*6) -> 172
A33: WR*Zaccheaus, Olamide - ATL | B33: 28 | C33: 17 | D33: =F33/E33 -> 0.63636364 | E33: 33 | F33: 21 | G33: 205 | H33: =G33/F33 -> 9.7619048 | I33: 2 | J33: =I33/F33 -> 0.095238095 | L33: 3 | M33: 16 | N33: =M33/L33 -> 5.3333333 | O33: 0 | P33: =O33/L33 -> 0 | S33: Zaccheaus, Olamide - ATL | T33: =(E33+L33)/($D$27+$L$27+$N$17+$E$47+$L$47) -> 0.048192771 | U33: =E33/($E$17) -> 0.090410959 | V33: =L33/($N$17+$D$27+$L$38+$L$47) -> 0.006147541 | X33: =($G33*('Scoring Format'!$B$4))+($I33*'Scoring Format'!$B$7)+($M33*('Scoring Format'!$B$3))+($O33*('Scoring Format'!$B$6)) -> 34.1 | Y33: =(F33*1)+(($G33*('Scoring Format'!$B$4))+($I33*'Scoring Format'!$B$7)+($M33*('Scoring Format'!$B$3))+($O33*('Scoring Format'!$B$6))) -> 55.1 | Z33: =(F33*0.5)+(($G33*('Scoring Format'!$B$4))+($I33*'Scoring Format'!$B$7)+($M33*('Scoring Format'!$B$3))+($O33*('Scoring Format'!$B$6))) -> 44.6 | AD33: Kirk, Christian- ARI | AF33: =AH33/AG33 -> 0.63333333 | AG33: 120 | AH33: 76 | AI33: 892 | AJ33: =AI33/AH33 -> 11.736842 | AK33: 5 | AL33: =AK33/AH33 -> 0.065789474 | AN33: 12 | AO33: 108 | AP33: =AO33/AN33 -> 9 | AQ33: 0 | AR33: =AQ33/AN33 -> 0 | AV33: =(#REF!+AK33)/(#REF!+AK36) -> #REF! | AW33: =#REF!/(AK33+#REF!) -> #REF! | AX33: =AK33/(#REF!+AK33) -> #REF! | AZ33: =(AI33*0.1)+(AK33*6)+(AO33*0.1)+(AQ33*6) -> 130 | BA33: =(AH33*1)+(AI33*0.1)+(AK33*6)+(AO33*0.1)+(AQ33*6) -> 206
A34: WR*Washington, Casey - ATL | B34: 25 | C34: 17 | D34: =F34/E34 -> 0.42857143 | E34: 7 | F34: 3 | G34: 47 | H34: =G34/F34 -> 15.666667 | I34: 0 | J34: =I34/F34 -> 0 | N34: =M34/L34 -> #DIV/0! | O34: 0 | P34: =O34/L34 -> #DIV/0! | S34: Washington, Casey - ATL | T34: =(E34+L34)/($D$27+$L$27+$N$17+$E$47+$L$47) -> 0.0093708166 | U34: =E34/($E$17) -> 0.019178082 | V34: =L34/($N$17+$D$27+$L$38+$L$47) -> 0 | X34: =($G34*('Scoring Format'!$B$4))+($I34*'Scoring Format'!$B$7)+($M34*('Scoring Format'!$B$3))+($O34*('Scoring Format'!$B$6)) -> 4.7 | Y34: =(F34*1)+(($G34*('Scoring Format'!$B$4))+($I34*'Scoring Format'!$B$7)+($M34*('Scoring Format'!$B$3))+($O34*('Scoring Format'!$B$6))) -> 7.7 | Z34: =(F34*0.5)+(($G34*('Scoring Format'!$B$4))+($I34*'Scoring Format'!$B$7)+($M34*('Scoring Format'!$B$3))+($O34*('Scoring Format'!$B$6))) -> 6.2 | AD34: Isabella, Andy - ARI | AF34: =AH34/AG34 -> 0.55 | AG34: 40 | AH34: 22 | AI34: 325 | AJ34: =AI34/AH34 -> 14.772727 | AK34: 2 | AL34: =AK34/AH34 -> 0.090909091 | AN34: 5 | AO34: 20 | AP34: =AO34/AN34 -> 4 | AQ34: 0 | AR34: =AQ34/AN34 -> 0 | AV34: =(#REF!+AK34)/(#REF!+AK37) -> #REF! | AW34: =#REF!/(AK34+#REF!) -> #REF! | AX34: =AK34/(#REF!+AK34) -> #REF! | AZ34: =(AI34*0.1)+(AK34*6)+(AO34*0.1)+(AQ34*6) -> 46.5 | BA34: =(AH34*1)+(AI34*0.1)+(AK34*6)+(AO34*0.1)+(AQ34*6) -> 68.5
A35: WR*Branch, Zachariah - ATL | B35: 22 | C35: 17 | D35: =F35/E35 -> 0.5 | E35: 20 | F35: 10 | G35: 90 | H35: =G35/F35 -> 9 | I35: 1 | J35: =I35/F35 -> 0.1 | N35: =M35/L35 -> #DIV/0! | O35: 1 | P35: =O35/L35 -> #DIV/0! | S35: Branch, Zachariah - ATL | T35: =(E35+L35)/($D$27+$L$27+$N$17+$E$47+$L$47) -> 0.026773762 | U35: =E35/($E$17) -> 0.054794521 | V35: =L35/($N$17+$D$27+$L$38+$L$47) -> 0 | X35: =($G35*('Scoring Format'!$B$4))+($I35*'Scoring Format'!$B$7)+($M35*('Scoring Format'!$B$3))+($O35*('Scoring Format'!$B$6)) -> 21 | Y35: =(F35*1)+(($G35*('Scoring Format'!$B$4))+($I35*'Scoring Format'!$B$7)+($M35*('Scoring Format'!$B$3))+($O35*('Scoring Format'!$B$6))) -> 31 | Z35: =(F35*0.5)+(($G35*('Scoring Format'!$B$4))+($I35*'Scoring Format'!$B$7)+($M35*('Scoring Format'!$B$3))+($O35*('Scoring Format'!$B$6))) -> 26 | AD35: Hopkins, DeAndre - ARI | AF35: =AH35/AG35 -> 0.66206897 | AG35: 145 | AH35: 96 | AI35: 1098 | AJ35: =AI35/AH35 -> 11.4375 | AK35: 7 | AL35: =AK35/AH35 -> 0.072916667 | AN35: 0 | AO35: 0 | AP35: =AO35/AN35 -> #DIV/0! | AQ35: 0 | AR35: =AQ35/AN35 -> #DIV/0! | AV35: =(#REF!+AK35)/(#REF!+AK38) -> #REF! | AW35: =#REF!/(AK35+#REF!) -> #REF! | AX35: =AK35/(#REF!+AK35) -> #REF! | AZ35: =(AI35*0.1)+(AK35*6)+(AO35*0.1)+(AQ35*6) -> 151.8 | BA35: =(AH35*1)+(AI35*0.1)+(AK35*6)+(AO35*0.1)+(AQ35*6) -> 247.8
A36: WR*Jahan Dotson, ATL | B36: 25 | C36: 17 | D36: =F36/E36 -> 0.63888889 | E36: 36 | F36: 23 | G36: 272 | H36: =G36/F36 -> 11.826087 | I36: 1 | J36: =I36/F36 -> 0.043478261 | N36: =M36/L36 -> #DIV/0! | O36: 0 | P36: =O36/L36 -> #DIV/0! | S36: Dotson, Jahan - ATL | T36: =(E36+L36)/($D$27+$L$27+$N$17+$E$47+$L$47) -> 0.048192771 | U36: =E36/($E$17) -> 0.098630137 | V36: =L36/($N$17+$D$27+$L$38+$L$47) -> 0 | X36: =($G36*('Scoring Format'!$B$4))+($I36*'Scoring Format'!$B$7)+($M36*('Scoring Format'!$B$3))+($O36*('Scoring Format'!$B$6)) -> 33.2 | Y36: =(F36*1)+(($G36*('Scoring Format'!$B$4))+($I36*'Scoring Format'!$B$7)+($M36*('Scoring Format'!$B$3))+($O36*('Scoring Format'!$B$6))) -> 56.2 | Z36: =(F36*0.5)+(($G36*('Scoring Format'!$B$4))+($I36*'Scoring Format'!$B$7)+($M36*('Scoring Format'!$B$3))+($O36*('Scoring Format'!$B$6))) -> 44.7 | AD36: Johnson, KeeSean - ARI | AF36: =AH36/AG36 -> 0.6 | AG36: 10 | AH36: 6 | AI36: 100 | AJ36: =AI36/AH36 -> 16.666667 | AK36: 0 | AL36: =AK36/AH36 -> 0 | AN36: 0 | AO36: 0 | AP36: =AO36/AN36 -> #DIV/0! | AQ36: 0 | AR36: =AQ36/AN36 -> #DIV/0! | AV36: =(#REF!+AK36)/(#REF!+AJ41) -> #REF! | AW36: =#REF!/(AK36+#REF!) -> #REF! | AX36: =AK36/(#REF!+AK36) -> #REF! | AZ36: =(AI36*0.1)+(AK36*6)+(AO36*0.1)+(AQ36*6) -> 10 | BA36: =(AH36*1)+(AI36*0.1)+(AK36*6)+(AO36*0.1)+(AQ36*6) -> 16
A37: WR*Anthony, Vinny - ATL | B37: 22 | C37: 17 | D37: =F37/E37 -> 0.5 | E37: 6 | F37: 3 | G37: 29 | H37: =G37/F37 -> 9.6666667 | I37: 0 | J37: =I37/F37 -> 0 | N37: =M37/L37 -> #DIV/0! | O37: 0 | P37: =O37/L37 -> #DIV/0! | S37: Anthony, Vinny - ATL | T37: =(E37+L37)/($D$27+$L$27+$N$17+$E$47+$L$47) -> 0.0080321285 | U37: =E37/($E$17) -> 0.016438356 | V37: =L37/($N$17+$D$27+$L$38+$L$47) -> 0 | X37: =($G37*('Scoring Format'!$B$4))+($I37*'Scoring Format'!$B$7)+($M37*('Scoring Format'!$B$3))+($O37*('Scoring Format'!$B$6)) -> 2.9 | Y37: =(F37*1)+(($G37*('Scoring Format'!$B$4))+($I37*'Scoring Format'!$B$7)+($M37*('Scoring Format'!$B$3))+($O37*('Scoring Format'!$B$6))) -> 5.9 | Z37: =(F37*0.5)+(($G37*('Scoring Format'!$B$4))+($I37*'Scoring Format'!$B$7)+($M37*('Scoring Format'!$B$3))+($O37*('Scoring Format'!$B$6))) -> 4.4 | AD37: Moore, Rondale - ARI | AF37: =AH37/AG37 -> #DIV/0! | AL37: =AK37/AH37 -> #DIV/0! | AP37: =AO37/AN37 -> #DIV/0! | AR37: =AQ37/AN37 -> #DIV/0! | AV37: =(#REF!+AK37)/(#REF!+AK42) -> #REF! | AW37: =#REF!/(AK37+#REF!) -> #REF! | AX37: =AK37/(#REF!+AK37) -> #REF!
A38: Total | E38: =SUM(E32:E37) -> 261 | F38: =SUM(F32:F37) -> 156 | G38: =SUM(G32:G37) -> 1943 | I38: =SUM(I32:I37) -> 14 | L38: =SUM(L32:L37) -> 3 | M38: =SUM(M32:M37) -> 16 | O38: =SUM(O32:O37) -> 1 | AD38: Total | AG38: =SUM(AG32:AG37) -> 422 | AH38: =SUM(AH32:AH37) -> 265 | AI38: =SUM(AI32:AI37) -> 3125 | AK38: =SUM(AK32:AK37) -> 20 | AN38: =SUM(AN32:AN37) -> 17 | AO38: =SUM(AO32:AO37) -> 128 | AQ38: =SUM(AQ32:AQ37) -> 0
A41: Receiving | K41: Rushing | S41: Touches | W41: Fantasy Points | AD41: Receiving | AM41: Rushing | AU41: Touches | AY41: Fantasy Points
A42: Tes | B42: Age | C42: G | D42: Catch % | E42: Targets | F42: Rec | G42: Yds | H42: Yds/Rec | I42: TDs | J42: TDs/Rec | L42: Ratt | M42: Ryds | N42: Ryds/Att | O42: RTDs | P42: TDs/Att | S42: Tes | T42: Touch % | U42: Pct Pass | V42: Pct Run | X42: Fpts | Y42: PPR Fpts | Z42: .5 PPR | AD42: Tes | AE42: G | AF42: Catch % | AG42: Targets | AH42: Rec | AI42: Yds | AJ42: Yds/Rec | AK42: TDs | AL42: TDs/Rec | AN42: Ratt | AO42: Ryds | AP42: Ryds/Att | AQ42: RTDs | AR42: TDs/Att | AV42: Touch % | AW42: Pct Pass | AX42: Pct Run | AZ42: Fpts | BA42: PPR Fpts
A43: TE*Pitts, Kyle - ATL | B43: 25 | C43: 17 | D43: =F43/E43 -> 0.66176471 | E43: 136 | F43: 90 | G43: 1028 | H43: =G43/F43 -> 11.422222 | I43: 6 | J43: =I43/F43 -> 0.066666667 | L43: 0 | M43: 0 | N43: 0 | O43: 0 | P43: =O43/L43 -> #DIV/0! | S43: Pitts, Kyle - ATL | T43: =(E43+L43)/($E$47+$L$47+$E$38+$L$38+$K$27+$D$27+$N$17) -> 0.13127413 | U43: =E43/($E$47+$E$38+$K$27) -> 0.24817518 | V43: =L43/($L$47+$L$38+$D$27+$N$17) -> 0 | X43: =($G43*('Scoring Format'!$B$4))+($I43*'Scoring Format'!$B$7)+($M43*('Scoring Format'!$B$3))+($O43*('Scoring Format'!$B$6)) -> 138.8 | Y43: =(F43*1)+(($G43*('Scoring Format'!$B$4))+($I43*'Scoring Format'!$B$7)+($M43*('Scoring Format'!$B$3))+($O43*('Scoring Format'!$B$6))) -> 228.8 | Z43: =(F43*0.5)+(($G43*('Scoring Format'!$B$4))+($I43*'Scoring Format'!$B$7)+($M43*('Scoring Format'!$B$3))+($O43*('Scoring Format'!$B$6))) -> 183.8 | AD43: Williams, Maxx - ARI | AF43: =AH43/AG43 -> 0.5625 | AG43: 16 | AH43: 9 | AI43: 108 | AJ43: =AI43/AH43 -> 12 | AK43: 1 | AL43: =AK43/AH43 -> 0.11111111 | AN43: 0 | AO43: 0 | AP43: 0 | AQ43: 0 | AR43: =AQ43/AN43 -> #DIV/0! | AV43: =(#REF!+AK43)/(#REF!+AK46) -> #REF! | AW43: =#REF!/(AK43+#REF!) -> #REF! | AX43: =AK43/(#REF!+AK43) -> #REF! | AZ43: =(AI43*0.1)+(AK43*6)+(AO43*0.1)+(AQ43*6) -> 16.8 | BA43: =(AH43*1)+(AI43*0.1)+(AK43*6)+(AO43*0.1)+(AQ43*6) -> 25.8
A44: TE*Woerner, Charlie - ATL | B44: 28 | C44: 16 | D44: =F44/E44 -> 0.77777778 | E44: 9 | F44: 7 | G44: 42 | H44: =G44/F44 -> 6 | I44: 0 | J44: =I44/F44 -> 0 | L44: 0 | M44: 0 | N44: 0 | O44: 0 | P44: =O44/L44 -> #DIV/0! | S44: Woerner, Charlie - ATL | T44: =(E44+L44)/($E$47+$L$47+$E$38+$L$38+$K$27+$D$27+$N$17) -> 0.0086872587 | U44: =E44/($E$47+$E$38+$K$27) -> 0.016423358 | V44: =L44/($L$47+$L$38+$D$27+$N$17) -> 0 | X44: =($G44*('Scoring Format'!$B$4))+($I44*'Scoring Format'!$B$7)+($M44*('Scoring Format'!$B$3))+($O44*('Scoring Format'!$B$6)) -> 4.2 | Y44: =(F44*1)+(($G44*('Scoring Format'!$B$4))+($I44*'Scoring Format'!$B$7)+($M44*('Scoring Format'!$B$3))+($O44*('Scoring Format'!$B$6))) -> 11.2 | Z44: =(F44*0.5)+(($G44*('Scoring Format'!$B$4))+($I44*'Scoring Format'!$B$7)+($M44*('Scoring Format'!$B$3))+($O44*('Scoring Format'!$B$6))) -> 7.7 | AD44: Daniels, Darenell - ARI | AF44: =AH44/AG44 -> 0.74285714 | AG44: 35 | AH44: 26 | AI44: 283 | AJ44: =AI44/AH44 -> 10.884615 | AK44: 2 | AL44: =AK44/AH44 -> 0.076923077 | AN44: 0 | AO44: 0 | AP44: 0 | AQ44: 0 | AR44: =AQ44/AN44 -> #DIV/0! | AV44: =(#REF!+AK44)/(#REF!+AK47) -> #REF! | AW44: =#REF!/(AK44+#REF!) -> #REF! | AX44: =AK44/(#REF!+AK44) -> #REF! | AZ44: =(AI44*0.1)+(AK44*6)+(AO44*0.1)+(AQ44*6) -> 40.3 | BA44: =(AH44*1)+(AI44*0.1)+(AK44*6)+(AO44*0.1)+(AQ44*6) -> 66.3
A45: TE*Hooper, Austin | B45: 31 | C45: 17 | D45: =F45/E45 -> 0.8 | E45: 25 | F45: 20 | G45: 180 | H45: =G45/F45 -> 9 | I45: 1 | J45: =I45/F45 -> 0.05 | L45: 0 | M45: 0 | N45: 0 | O45: 0 | P45: =O45/L45 -> #DIV/0! | S45: Hooper, Austin - ATL | T45: =(E45+L45)/($E$47+$L$47+$E$38+$L$38+$K$27+$D$27+$N$17) -> 0.024131274 | U45: =E45/($E$47+$E$38+$K$27) -> 0.045620438 | V45: =L45/($L$47+$L$38+$D$27+$N$17) -> 0 | X45: =($G45*('Scoring Format'!$B$4))+($I45*'Scoring Format'!$B$7)+($M45*('Scoring Format'!$B$3))+($O45*('Scoring Format'!$B$6)) -> 24 | Y45: =(F45*1)+(($G45*('Scoring Format'!$B$4))+($I45*'Scoring Format'!$B$7)+($M45*('Scoring Format'!$B$3))+($O45*('Scoring Format'!$B$6))) -> 44 | Z45: =(F45*0.5)+(($G45*('Scoring Format'!$B$4))+($I45*'Scoring Format'!$B$7)+($M45*('Scoring Format'!$B$3))+($O45*('Scoring Format'!$B$6))) -> 34 | AD45: Bunting, Ian - ARI | AF45: =AH45/AG45 -> 0.5 | AG45: 12 | AH45: 6 | AI45: 65 | AJ45: =AI45/AH45 -> 10.833333 | AK45: 0 | AL45: =AK45/AH45 -> 0 | AN45: 0 | AO45: 0 | AP45: 0 | AQ45: 0 | AR45: =AQ45/AN45 -> #DIV/0! | AV45: =(#REF!+AK45)/(#REF!+AJ49) -> #REF! | AW45: =#REF!/(AK45+#REF!) -> #REF! | AX45: =AK45/(#REF!+AK45) -> #REF! | AZ45: =(AI45*0.1)+(AK45*6)+(AO45*0.1)+(AQ45*6) -> 6.5 | BA45: =(AH45*1)+(AI45*0.1)+(AK45*6)+(AO45*0.1)+(AQ45*6) -> 12.5
D46: =F46/E46 -> #DIV/0! | H46: =G46/F46 -> #DIV/0! | I46: 0 | J46: =I46/F46 -> #DIV/0! | N46: 0 | O46: 0 | P46: =O46/L46 -> #DIV/0! | T46: =(E46+L46)/($E$47+$L$47+$E$38+$L$38+$K$27+$D$27+$N$17) -> 0 | U46: =E46/($E$47+$E$38+$K$27) -> 0 | V46: =L46/($L$47+$L$38+$D$27+$N$17) -> 0 | X46: =($G46*('Scoring Format'!$B$4))+($I46*'Scoring Format'!$B$7)+($M46*('Scoring Format'!$B$3))+($O46*('Scoring Format'!$B$6)) -> 0 | Y46: =(F46*1)+(($G46*('Scoring Format'!$B$4))+($I46*'Scoring Format'!$B$7)+($M46*('Scoring Format'!$B$3))+($O46*('Scoring Format'!$B$6))) -> 0 | Z46: =(F46*0.5)+(($G46*('Scoring Format'!$B$4))+($I46*'Scoring Format'!$B$7)+($M46*('Scoring Format'!$B$3))+($O46*('Scoring Format'!$B$6))) -> 0 | AF46: =AH46/AG46 -> #DIV/0! | AJ46: =AI46/AH46 -> #DIV/0! | AL46: =AK46/AH46 -> #DIV/0! | AQ46: 0 | AR46: =AQ46/AN46 -> #DIV/0! | AV46: =(#REF!+AK46)/(#REF!+AJ50) -> #REF! | AW46: =#REF!/(AK46+#REF!) -> #REF! | AX46: =AK46/(#REF!+AK46) -> #REF! | AZ46: =(AI46*0.1)+(AK46*6)+(AO46*0.1)+(AQ46*6) -> 0 | BA46: =(AH46*1)+(AI46*0.1)+(AK46*6)+(AO46*0.1)+(AQ46*6) -> 0
A47: Total | E47: =SUM(E43:E46) -> 170 | F47: =SUM(F43:F46) -> 117 | G47: =SUM(G43:G46) -> 1250 | I47: =SUM(I43:I46) -> 7 | L47: =SUM(L43:L46) -> 0 | M47: =SUM(M43:M46) -> 0 | O47: =SUM(O43:O46) -> 0 | AD47: Total | AG47: =SUM(AG43:AG46) -> 63 | AH47: =SUM(AH43:AH46) -> 41 | AI47: =SUM(AI43:AI46) -> 456 | AK47: =SUM(AK43:AK46) -> 3 | AN47: =SUM(AN43:AN46) -> 0 | AO47: =SUM(AO43:AO46) -> 0 | AQ47: =SUM(AQ43:AQ46) -> 0
A50: Team Totals and Splits | K50: Taxi Squad* | S50: Injured Reserve | AD50: Team Totals and Splits | AM50: Taxi Squad* | AU50: Injured Reserve
C51: Targets | D51: Rec. | E51: Yds | F51: TDs | J51: Player | N51: Position | R51: Player | V51: Position | AE51: Targets | AF51: Rec. | AG51: Yds | AH51: TDs | AM51: Player | AQ51: Position | AU51: Player | AY51: Position
A52: Rec Totals | C52: =SUM(K22:K26,E32:E37,E43:E46) -> 548 | D52: =SUM(F43:F46,F32:F37,L22:L26) -> 365 | E52: =SUM(G43:G46,G32:G37,M22:M26) -> 3964 | F52: =SUM(O22:O26,I32:I37,I43:I46) -> 24 | J52: Nathan Carter | N52: RB | AC52: Rec Totals | AD52: =SUM(AM22:AM26,AG32:AG37,AG43:AG46) -> 583 | AE52: =SUM(AH43:AH46,AH32:AH37,AM22:AM26) -> 404 | AF52: =SUM(AI43:AI46,AI32:AI37,AN22:AN26) -> 3653 | AG52: =SUM(AQ22:AQ26,AK32:AK37,AK43:AK46) -> 27
...

Sheet BALT
A1: Baltimore Ravens
A3: Team Projections Menu | AC3: Team Projections Menu
H5: RSP Projections: Year 1 | M5: Adjustable Projections: Year 1 | S5: Offense Distribution | AJ5: RSP Projections: Year 1 | AO5: Adjustable Projections: Year 1
H6: RSP Projections: Year 2 | M6: Past Run/Pass Performances | S6: Run | T6: Pass | AJ6: RSP Projections: Year 2
S7: =(N17+D27+L38+L47)/(N17+D27+L38+D17) -> 0.53134041 | T7: =D17/(D17+N17+D27+L38+L47) -> 0.46865959
A10: RSP Projections: Year 1 | AC10: Adjustable Projections: Year 1
C12: Passing | L12: Rushing | R12: Touches | V12: Fantasy Points | AE12: Passing | AN12: Rushing | AT12: Touches | AX12: Fantasy Points
A13: QB | B13: Age | C13: G | D13: Att | E13: Comp | F13: Pct | G13: Yards | H13: Yds/Att | I13: TDs | J13: TDs/Att | K13: Int | L13: Int/Att | N13: Ratt | O13: Ryds | P13: Ryds/Att | Q13: TDs | R13: Tds/Att | T13: Touch % | U13: Pct Pass | V13: Pct Run | X13: Fpts | Y13: Adjusted | AD13: QB | AE13: G | AF13: Att | AG13: Comp | AH13: Pct | AI13: Yards | AJ13: Yds/Att | AK13: TDs | AL13: TDs/Att | AM13: Int | AN13: Int/Att | AP13: Ratt | AQ13: Ryds | AR13: Ryds/Att | AS13: TDs | AT13: Tds/Att | AV13: Touch % | AW13: Pct Pass | AX13: Pct Run | AZ13: Fpts | BA13: Adjusted
